Workbook

Sheet Component
A1: Component designation
A2: Author: | B2: Artjom Lukanowski
A3: Date: | B3: 07.03.2026
H4: No. | I4: Name
H5: 1 | I5: GIMBAL RING
H6: 2 | I6: SHIM
H7: 3 | I7: PIN
H8: 4 | I8: BEARING
H9: 5 | I9: GIMBAL LOWER SUPPORT
H10: 6 | I10: INJECTION HEAD

Sheet FMEA
A1: FAILURE MODE EFFECT ANALYSIS (FMEA)
A2: Author: | B2: Artjom Lukanowski
A3: Date: | B3: 07.03.2026
A4: Reference no. | B4: Item Name | C4: Function | D4: Failure Mode | E4: Failure Causes | F4: Mission Phase/Op. mode | G4: Local effect on part | H4: Global (end) effect on component | I4: Severity classification | J4: Failure Detection Method | K4: Compensating provisions | L4: Severity Number | M4: Probability/Occurance | N4: Criticality | O4: Recommendations | P4: Remarks
A5: 1 | B5: GIMBAL LOWER/UPPER SUPPORT | C5: Structural connection of injector head to the gimbal mount assembly, allowing pivoting for thrust vectoring and transmitting mechanical and thermal loads | D5: Misalignment to injector head | E5: Assembly tolerance stack-up, improper positioning | F5: Integration | G5: Uneven interface loading | H5: Gimbal axis and thrust misalignment, hindered gimbal motion | I5: Major | J5: CAD and tolerance analysis | K5: Alignment shims | L5: 4 | M5: 3 | N5: =VLOOKUP(L5&M5,Class!$T$3:$U$26,2,FALSE) -> ME | O5: Tight tolerance control, alignment measurement during integration | P5: Unpredicted loading on TVC actuators and critical thrust vector accuracy | R5: =L5&M5 -> 43 | S5: =IF(R5<>"",1,0) -> 1
A6: 2 | D6: Incorrect bolt preload | E6: Torque error, friction deviation | G6: Joint slip under load or overtorqued bolt | H6: Reduced stiffness of gimbal mount | I6: Major | J6: Torque verification | K6: Calibrated tools and assembly preocedures | L6: 4 | M6: 4 | N6: =VLOOKUP(L6&M6,Class!$T$3:$U$26,2,FALSE) -> HI | O6: Use torque and angle/preload verification, aerospace rated (tested) joints | P6: Friction variability risk with standard fasteners | R6: =L6&M6 -> 44 | S6: =IF(R6<>"",1,0) -> 1
A7: 3 | D7: Loss of bolt preload at injector interface | E7: Differential thermal contraction during chill-down or start transient | F7: Start-Up | G7: Reduced clamping force at joint | H7: Reduced stiffness of gimbal mount | I7: Major | J7: Structural/thermal analysis, test | K7: Preload margin, high-strength fasteners | L7: 4 | M7: 3 | N7: =VLOOKUP(L7&M7,Class!$T$3:$U$26,2,FALSE) -> ME | O7: Verify preload with thermal transient model | P7: Driver: Cryogenic contraction and small fasteners with low material properties | R7: =L7&M7 -> 43 | S7: =IF(R7<>"",1,0) -> 1
A8: 4 | D8: Joint slip at injector interface | E8: Insufficient preload combined with ignition load transient | G8: Micro-motion, fretting at interface | H8: Changing load redistribution into fasteners / support | I8: Major | J8: Dynamic load simulation | K8: Increased preload, friction at interface | L8: 4 | M8: 3 | N8: =VLOOKUP(L8&M8,Class!$T$3:$U$26,2,FALSE) -> ME | O8: High-friction interfaces | P8: High friction interfaces impacts fastener preload losses and heat transfer | R8: =L8&M8 -> 43 | S8: =IF(R8<>"",1,0) -> 1
A9: 5 | D9: Yielding / permanent deformation | E9: Peak thrust and transient dynamic loads underpredicted during analysis | G9: Plastic strain at fillets, bolt holes etc. | H9: Gimbal axis offset, misalignment, reduced load margin | I9: Critical | J9: FEA structural verification | K9: Conservative stress and deformation margins | L9: 5 | M9: 2 | N9: =VLOOKUP(L9&M9,Class!$T$3:$U$26,2,FALSE) -> ME | O9: Increase fillet radii, amount of notches, thickness/stiffness if margin low | P9: Peak thrust case | R9: =L9&M9 -> 52 | S9: =IF(R9<>"",1,0) -> 1
A10: 6 | D10: Fatigue crack initiation | E10: Cyclic loads from thrust vectoring and engine vibration | F10: Steady State | G10: Crack formation in high-stress region | H10: Progressive loss of structural margin | I10: Critical | J10: LCF analysis | K10: Conservative stress margins | L10: 5 | M10: 3 | N10: =VLOOKUP(L10&M10,Class!$T$3:$U$26,2,FALSE) -> HI | O10: Improve surface finish, reduce stress concentrators | P10: - | R10: =L10&M10 -> 53 | S10: =IF(R10<>"",1,0) -> 1
A11: 7 | D11: Bearing seat deformation | E11: High oscillatory loads transmitted through pin | G11: Local crushing or ovalization of contact region | H11: Loss of geometric alignment | I11: Major | J11: Contact stress analysis | K11: Hard surface materials, adequate wall thickness | L11: 4 | M11: 3 | N11: =VLOOKUP(L11&M11,Class!$T$3:$U$26,2,FALSE) -> ME | O11: Verify bearing seat stress limits | P11: Driven by oscillatory loads, prediction of th./mech. Load cases and chosen fit between shaft /hub | R11: =L11&M11 -> 43 | S11: =IF(R11<>"",1,0) -> 1
A12: 8 | D12: Pin–hole misfit due to thermal misestimation | E12: Incorrect prediction of thermal contraction of support vs. pin | G12: Increased contact stress, local yielding, or micro-motion at hole | H12: Accelerated fatigue, risk of gimbal axis misalignment | I12: Major | J12: Thermal-structural analysis | K12: Thermal margin in fit design | L12: 4 | M12: 3 | N12: =VLOOKUP(L12&M12,Class!$T$3:$U$26,2,FALSE) -> ME | O12: Check thermal assumptions for thermal expansion | P12: Sensitive to temperature uncertainty, pin is more prone of failure here | R12: =L12&M12 -> 43 | S12: =IF(R12<>"",1,0) -> 1
A13: 9 | D13: Micro-crack propagation | E13: Residual stress from previous operation | F13: Shut Down | G13: Crack growth in fillets or other notches | H13: Accelerated fatigue risk for next operation phase | I13: Major | J13: LCF analysis | K13: Structural margin and inspection | L13: 4 | M13: 2 | N13: =VLOOKUP(L13&M13,Class!$T$3:$U$26,2,FALSE) -> MI | O13: Verify crack growth margin | P13: Relevant for reuse | R13: =L13&M13 -> 42 | S13: =IF(R13<>"",1,0) -> 1
A14: 10 | D14: Fasteners inaccessible | E14: Tight packaging around injector head or gimbal assembly | F14: Inspection | G14: Bolts cannot be removed for inspection | H14: Interface cannot be reviewed, potential hidden damage remains | I14: Minor | J14: Assembly review | K14: Access ports or removable panels | L14: 2 | M14: 4 | N14: =VLOOKUP(L14&M14,Class!$T$3:$U$26,2,FALSE) -> MI | O14: Ensure tool access clearance | P14: Maintainability issue | R14: =L14&M14 -> 24 | S14: =IF(R14<>"",1,0) -> 1
A15: 11 | D15: Misalignment not measurable | E15: Lack of clear reference points or measurement tools | G15: Small gimbal axis offsets remain unverified | H15: Cumulative misalignment affecting future operation and overloading parts | I15: Minor | J15: Inspection | K15: Reference surfaces, measurement points | L15: 2 | M15: 3 | N15: =VLOOKUP(L15&M15,Class!$T$3:$U$26,2,FALSE) -> MI | O15: Add alignment datums | P15: Importance for reintegration | R15: =L15&M15 -> 23 | S15: =IF(R15<>"",1,0) -> 1
A16: 12 | D16: Pin and bearing condition unknown | E16: Limited access or visibility | G16: Undetected wear or deformation | H16: Altered load path or reduced support stiffness during next operation | I16: Major | J16: Visual inspection, NDT | K16: Removable covers, brackets | L16: 4 | M16: 3 | N16: =VLOOKUP(L16&M16,Class!$T$3:$U$26,2,FALSE) -> ME | O16: Provide inspection acces, sensor monitoring, rotation marks | P16: Hidden wear risk | R16: =L16&M16 -> 43 | S16: =IF(R16<>"",1,0) -> 1
A17: 13 | B17: PIN | C17: Structural pivot and load-transfer connection, enabling precise thrust vectoring while caryying bending, shear and oscillatory loads | D17: Incorrect fit | E17: Manufacturing tolerance stack-up, improper analysis | F17: Integration | G17: Excessive clearance or interference fit | H17: Gimbal axis misalignment, uneven load transfer | I17: Major | J17: Dimensional inspection, fit check | K17: Tight manufacturing tolerances, inspection | L17: 4 | M17: 3 | N17: =VLOOKUP(L17&M17,Class!$T$3:$U$26,2,FALSE) -> ME | O17: Strict quality control | P17: Critical for correct alignment | R17: =L17&M17 -> 43 | S17: =IF(R17<>"",1,0) -> 1
A18: 14 | D18: Plastic deformation | E18: Peak transient thrust and dynamic loads exceeding yield | F18: Start-Up | G18: Localized bending or indentation on edges | H18: Potential gimbal axis offset, reduced margin | I18: Critical | J18: Structural FEA, visual inspection | K18: Conservative safety factors, material choice | L18: 5 | M18: 2 | N18: =VLOOKUP(L18&M18,Class!$T$3:$U$26,2,FALSE) -> ME | O18: Increase cross-section, material strength, add heat treatment | P18: Peak transient thrust case | R18: =L18&M18 -> 52 | S18: =IF(R18<>"",1,0) -> 1
A19: 15 | D19: Joint slip / micro-movement | E19: Insufficient preload, thermal mismatch | G19: Wear or galling | H19: Load redistribution, accelerated fatigue, limited inspection capability | I19: Major | J19: Wear inspection, vibration analysis | K19: Increased preload, use of wear-resistant coatings | L19: 4 | M19: 3 | N19: =VLOOKUP(L19&M19,Class!$T$3:$U$26,2,FALSE) -> ME | O19: Introduce high friction surface | P19: High friction may limit inspection capability | R19: =L19&M19 -> 43 | S19: =IF(R19<>"",1,0) -> 1
A20: 16 | D20: Fatigue crack initiation | E20: Cyclic bending and shear stresses from gimbal motion | F20: Steady State | G20: Crack formation at high-stress locations | H20: Progressive structural weakening, potential failure | I20: Critical | J20: NDT | K20: Design margins, surface finish control | L20: 5 | M20: 3 | N20: =VLOOKUP(L20&M20,Class!$T$3:$U$26,2,FALSE) -> HI | O20: Regular inspection, material certificates / tests | P20: Very limited access for inspection | R20: =L20&M20 -> 53 | S20: =IF(R20<>"",1,0) -> 1
A21: 17 | D21: Galling | E21: Adhesive bonding of mating materials in hard-hard material pairing condition | G21: Not dismountable without distruction | H21: No inspection and replacement of connected parts | I21: Major | J21: Visual inspection, disassembly | K21: Use compatible materials, lubricants | L21: 4 | M21: 2 | N21: =VLOOKUP(L21&M21,Class!$T$3:$U$26,2,FALSE) -> MI | O21: Avoid hard-hard contact, use coatings | P21: Limits maintanance options | R21: =L21&M21 -> 42 | S21: =IF(R21<>"",1,0) -> 1
A22: 18 | D22: Wear / fretting | E22: Micro-motion between pin and bore interfaces in hard-soft material condition | G22: Material loss | H22: Increased clearance, reduced stiffness | I22: Major | J22: Wear debris, analysis | K22: Harder materials, proper fit tolerances | L22: 4 | M22: 3 | N22: =VLOOKUP(L22&M22,Class!$T$3:$U$26,2,FALSE) -> ME | O22: Monitor wear, provide inspection access | P22: Wear reduces stiffness, and lifetime, less shock resistancy | R22: =L22&M22 -> 43 | S22: =IF(R22<>"",1,0) -> 1
A23: 19 | D23: Accessibility limitations | E23: Tight interference fit due underpredicted thermal loads | F23: Inspection | G23: Pin not dismountable | H23: Remaining parts not accessible | I23: Minor | J23: Assembly review | K23: Design for dissasembly | L23: 2 | M23: 4 | N23: =VLOOKUP(L23&M23,Class!$T$3:$U$26,2,FALSE) -> MI | O23: Provide tool access, disassembly planning | P23: Impacts maintanability | R23: =L23&M23 -> 24 | S23: =IF(R23<>"",1,0) -> 1
A24: 20 | D24: Accessibility limitations | E24: Tight assembly, obstruction by other components | G24: Incomplete visual or NDT coverage | H24: Undetected cracks or wear | I24: Minor | J24: Visual inspection, NDT | K24: Access ports or removable covers | L24: 2 | M24: 3 | N24: =VLOOKUP(L24&M24,Class!$T$3:$U$26,2,FALSE) -> MI | O24: Improve inspection access | P24: Risk of hidden damages | R24: =L24&M24 -> 23 | S24: =IF(R24<>"",1,0) -> 1
A25: 21 | B25: SHIM | C25: Defines axial position of the bearing inner race and sets minimum distance between lower support and cardan ring to adjust thrust alignment | D25: Incorrect shim thickness | E25: Assembly error, wrong selection | F25: Integration | G25: Mispositioned bearing | H25: Thrust misalignment | I25: Minor | J25: Dimensional inspection | K25: Use standardized shim kits, assembly checks | L25: 4 | M25: 2 | N25: =VLOOKUP(L25&M25,Class!$T$3:$U$26,2,FALSE) -> MI | O25: Document and improve assembly procedures | P25: Critical for correct alignment | R25: =L25&M25 -> 42 | S25: =IF(R25<>"",1,0) -> 1
A26: 22 | D26: Improper shim seating | E26: Assembly error, debris, surface damage | G26: Non-uniform load distribution | H26: Increased bearing stress | I26: Major | J26: Visual inspection | K26: Clean surfaces | L26: 4 | M26: 3 | N26: =VLOOKUP(L26&M26,Class!$T$3:$U$26,2,FALSE) -> ME | O26: Include cleaning requirements for assembly | P26: Causes early wear if not hardened | R26: =L26&M26 -> 43 | S26: =IF(R26<>"",1,0) -> 1
A27: 23 | D27: Plastic deformation | E27: Sudden thrust load, excessive preload | F27: Start-Up | G27: Permanent thickness change | H27: Shift in thrust alignment, misplaced bearing | I27: Minor | J27: Visual inspection, NDT | K27: Margin in shim thickness | L27: 3 | M27: 2 | N27: =VLOOKUP(L27&M27,Class!$T$3:$U$26,2,FALSE) -> MI | O27: Increase min. shim thickness margin | P27: Shim carries mainly axial loads, if plastic def. occurs, it will be marginal. Fracture is more severe | R27: =L27&M27 -> 32 | S27: =IF(R27<>"",1,0) -> 1
A28: 24 | D28: Wear | E28: Micro-motion due to vibration and oscillation loads or relative motion between lower support and pin | F28: Steady State | G28: Surface damage, thickness reduction | H28: Alignment drift | I28: Minor | J28: Visual inspection, thicknes measurement | K28: Use ardened shims | L28: 3 | M28: 3 | N28: =VLOOKUP(L28&M28,Class!$T$3:$U$26,2,FALSE) -> MI | O28: Frequent inspection, replacement if needed | P28: Shims in hardened condition | R28: =L28&M28 -> 33 | S28: =IF(R28<>"",1,0) -> 1
A29: 25 | D29: Residual deformation | E29: Load relaxation and peak stress history | F29: Shut Down | G29: Permanent geometric change | H29: Alignment shift | I29: Minor | J29: Visual inspection, sensors | K29: Use high yield strength material | L29: 4 | M29: 2 | N29: =VLOOKUP(L29&M29,Class!$T$3:$U$26,2,FALSE) -> MI | O29: Monitor deformation by sensors, visualy, replace if needed | P29: Reusability affected, hardened shims will rather break immediately | R29: =L29&M29 -> 42 | S29: =IF(R29<>"",1,0) -> 1
A30: 26 | D30: Fracture | E30: Preceding bear load history and wear | G30: Break of shim | H30: Broken and loosened parts may block gimbal motion | I30: Critical | J30: Visual inspection, NDT | K30: Use fracture-resistant material | L30: 4 | M30: 1 | N30: =VLOOKUP(L30&M30,Class!$T$3:$U$26,2,FALSE) -> LO | O30: Inspection prior utilization | P30: Can cause mech. Jamming | R30: =L30&M30 -> 41 | S30: =IF(R30<>"",1,0) -> 1
A31: 27 | D31: Surface damage detected | E31: Fretting or overload | F31: Inspection | G31: Visible wear or deformation | H31: Need for replacement before reuse | I31: Major | J31: Visual inspection, NDT | K31: Inspection access, replacement possibility | L31: 4 | M31: 3 | N31: =VLOOKUP(L31&M31,Class!$T$3:$U$26,2,FALSE) -> ME | O31: Anticipate for replacement | P31: Wear accumulates over cycles (reusability) | R31: =L31&M31 -> 43 | S31: =IF(R31<>"",1,0) -> 1
A32: 28 | D32: Incorrect shim thickness | E32: Assembly error, wrong selection | G32: Mispositioned bearing | H32: Thrust misalignment | I32: Major | J32: Dimensional inspection | K32: Assembly check | L32: 4 | M32: 3 | N32: =VLOOKUP(L32&M32,Class!$T$3:$U$26,2,FALSE) -> ME | O32: Confirm correct shim thickness | P32: Double-check during inspection | R32: =L32&M32 -> 43 | S32: =IF(R32<>"",1,0) -> 1
A33: 29 | D33: Thickness change detected | E33: Plastic deformation during operation or wear | G33: Out-of-tolerance geometry | H33: Re-adjustment of thrust alignment required | I33: Minor | J33: Regular measurement | K33: Detect early deformation or wear | L33: 3 | M33: 3 | N33: =VLOOKUP(L33&M33,Class!$T$3:$U$26,2,FALSE) -> MI | O33: Frequent inspection | P33: Detect early deformation/wear | R33: =L33&M33 -> 33 | S33: =IF(R33<>"",1,0) -> 1
A34: 30 | B34: BEARING | C34: Permits ngular misalignment while transferring radial loads from engine supports to cardan ring. | D34: Improper bearing seating in cardan ring pocket | E34: Incorrect interference fit, assembly misalignment | F34: Integration | G34: Non-uniform load distribution in bearing | H34: Reduced bearing life | I34: Major | J34: Dimensional inspection, press force monitoring | K34: Use calibrated tools, assembly procedures | L34: 4 | M34: 3 | N34: =VLOOKUP(L34&M34,Class!$T$3:$U$26,2,FALSE) -> ME | O34: Strict assembly control | P34: - | R34: =L34&M34 -> 43 | S34: =IF(R34<>"",1,0) -> 1
A35: 31 | D35: Bearing damage during installation | E35: Excessive press force, improper tools / tool alignment | G35: Damage to PTFE liner or race surface | H35: Reduced articulation capability | I35: Major | J35: Visual inspection | K35: Proper tooling, training | L35: 4 | M35: 2 | N35: =VLOOKUP(L35&M35,Class!$T$3:$U$26,2,FALSE) -> MI | O35: Proper tooling, training | P35: Prevent damage during install | R35: =L35&M35 -> 42 | S35: =IF(R35<>"",1,0) -> 1
A36: 32 | D36: Local PTFE liner damage | E36: Vibration, high radial loads, improper fit | F36: Start-Up | G36: Local wear or liner deformation | H36: Increased bearing clearance, uncertain friction behavior, reduced bearing life | I36: Major | J36: Visual inspection, NDT | K36: Material selection, correct fit | L36: 4 | M36: 3 | N36: =VLOOKUP(L36&M36,Class!$T$3:$U$26,2,FALSE) -> ME | O36: Monitor liner condition | P36: Affects prediction of friction and bearing life | R36: =L36&M36 -> 43 | S36: =IF(R36<>"",1,0) -> 1
A37: 33 | D37: Outer race micro-movement | E37: Insufficient fit in pocket, load spike | G37: Fretting between race and housing | H37: Reduced retention of bearing | I37: Major | J37: Wear debris, grinding marks | K37: correct interference fit | L37: 4 | M37: 3 | N37: =VLOOKUP(L37&M37,Class!$T$3:$U$26,2,FALSE) -> ME | O37: Inspect fit, adjust tolerances | P37: Loosening reduces stiffness and reusability | R37: =L37&M37 -> 43 | S37: =IF(R37<>"",1,0) -> 1
A38: 34 | D38: PTFE liner wear | E38: Oscillatory motion, vibration, high radial loads, improper fitting (inner/outer race) | F38: Steady State | G38: Increased internal clearance | H38: Reduced gimbal stiffness, bearing life, higher pin loads | I38: Major | J38: Visual inspection | K38: High-quality liners, correct assembly | L38: 4 | M38: 3 | N38: =VLOOKUP(L38&M38,Class!$T$3:$U$26,2,FALSE) -> ME | O38: Replace bearings, consider in spare part policy | P38: Wear reduces stiffness, and lifetime, less shock resistancy | R38: =L38&M38 -> 43 | S38: =IF(R38<>"",1,0) -> 1
A39: 35 | D39: Damaged PTFE liner through environment | E39: Environmental sand corn, dust etc. | G39: Increase of wear, friction characteristics, bearing life | H39: Loss of control authority during TVC actuation | I39: Major | J39: Visual inspection,sensors, cameras | K39: Protection | L39: 4 | M39: 4 | N39: =VLOOKUP(L39&M39,Class!$T$3:$U$26,2,FALSE) -> HI | O39: Cover by light-weight material, bearings with sealing lips | P39: Bearings with seals impact the breaking torque and friction anticipation for TVC actuators | R39: =L39&M39 -> 44 | S39: =IF(R39<>"",1,0) -> 1
A40: 36 | D40: Bearing seizure / restricted motion | E40: Overload, liner degradation | G40: Limited rotation capability of spherical joint | H40: Impaired gimbal movement | I40: Critical | J40: Actuation test | K40: Load limits, inspection | L40: 5 | M40: 2 | N40: =VLOOKUP(L40&M40,Class!$T$3:$U$26,2,FALSE) -> ME | O40: Tests via actautors before and after each hot fire, limit loads, inspect after each operation | P40: Impacts gimbal motion if occures at surfaces that are in relative motion | R40: =L40&M40 -> 52 | S40: =IF(R40<>"",1,0) -> 1
...

Sheet Class
C2: Probability, Severity, Criticality Synthesis | R2: S | S2: P | T2: SG | U2: C
I3: Criticality | K3: Severity | R3: =K4 -> 1 | S3: =J5 -> 5 | T3: =R3&S3 -> 15 | U3: MI
K4: 1 | L4: 2 | M4: 3 | N4: 4 | O4: 5 | R4: =L4 -> 2 | S4: =S3 -> 5 | T4: =R4&S4 -> 25 | U4: ME
F5: TEC-FRA-DOC-2025-01603 | I5: Probability | J5: 5 | K5: =SUMIF(FMEA!$R:$R,Class!K$4&Class!$J5,FMEA!$S:$S) -> 0 | L5: =SUMIF(FMEA!$R:$R,Class!L$4&Class!$J5,FMEA!$S:$S) -> 0 | M5: =SUMIF(FMEA!$R:$R,Class!M$4&Class!$J5,FMEA!$S:$S) -> 0 | N5: =SUMIF(FMEA!$R:$R,Class!N$4&Class!$J5,FMEA!$S:$S) -> 0 | O5: =SUMIF(FMEA!$R:$R,Class!O$4&Class!$J5,FMEA!$S:$S) -> 0 | R5: =M4 -> 3 | S5: =S4 -> 5 | T5: =R5&S5 -> 35 | U5: HI
C6: Probability | J6: 4 | K6: =SUMIF(FMEA!$R:$R,Class!K$4&Class!$J6,FMEA!$S:$S) -> 0 | L6: =SUMIF(FMEA!$R:$R,Class!L$4&Class!$J6,FMEA!$S:$S) -> 2 | M6: =SUMIF(FMEA!$R:$R,Class!M$4&Class!$J6,FMEA!$S:$S) -> 0 | N6: =SUMIF(FMEA!$R:$R,Class!N$4&Class!$J6,FMEA!$S:$S) -> 2 | O6: =SUMIF(FMEA!$R:$R,Class!O$4&Class!$J6,FMEA!$S:$S) -> 0 | R6: =N4 -> 4 | S6: =S5 -> 5 | T6: =R6&S6 -> 45 | U6: VH
J7: 3 | K7: =SUMIF(FMEA!$R:$R,Class!K$4&Class!$J7,FMEA!$S:$S) -> 0 | L7: =SUMIF(FMEA!$R:$R,Class!L$4&Class!$J7,FMEA!$S:$S) -> 2 | M7: =SUMIF(FMEA!$R:$R,Class!M$4&Class!$J7,FMEA!$S:$S) -> 2 | N7: =SUMIF(FMEA!$R:$R,Class!N$4&Class!$J7,FMEA!$S:$S) -> 21 | O7: =SUMIF(FMEA!$R:$R,Class!O$4&Class!$J7,FMEA!$S:$S) -> 4 | R7: =O4 -> 5 | S7: =S6 -> 5 | T7: =R7&S7 -> 55 | U7: VH
C8: Score | D8: Likelihood | E8: Probability quantitative value | J8: 2 | K8: =SUMIF(FMEA!$R:$R,Class!K$4&Class!$J8,FMEA!$S:$S) -> 0 | L8: =SUMIF(FMEA!$R:$R,Class!L$4&Class!$J8,FMEA!$S:$S) -> 0 | M8: =SUMIF(FMEA!$R:$R,Class!M$4&Class!$J8,FMEA!$S:$S) -> 1 | N8: =SUMIF(FMEA!$R:$R,Class!N$4&Class!$J8,FMEA!$S:$S) -> 6 | O8: =SUMIF(FMEA!$R:$R,Class!O$4&Class!$J8,FMEA!$S:$S) -> 5 | R8: =R3 -> 1 | S8: =J6 -> 4 | T8: =R8&S8 -> 14 | U8: MI
C9: 5 | D9: Very Probable | E9: P ≥ 10-1 | J9: 1 | K9: =SUMIF(FMEA!$R:$R,Class!K$4&Class!$J9,FMEA!$S:$S) -> 0 | L9: =SUMIF(FMEA!$R:$R,Class!L$4&Class!$J9,FMEA!$S:$S) -> 0 | M9: =SUMIF(FMEA!$R:$R,Class!M$4&Class!$J9,FMEA!$S:$S) -> 0 | N9: =SUMIF(FMEA!$R:$R,Class!N$4&Class!$J9,FMEA!$S:$S) -> 1 | O9: =SUMIF(FMEA!$R:$R,Class!O$4&Class!$J9,FMEA!$S:$S) -> 0 | R9: =R4 -> 2 | S9: =S8 -> 4 | T9: =R9&S9 -> 24 | U9: MI
C10: 4 | D10: Probable | E10: 10-1 > P ≥ 10-3 | R10: =R5 -> 3 | S10: =S9 -> 4 | T10: =R10&S10 -> 34 | U10: ME
C11: 3 | D11: Little Probable | E11: 10-3 > P ≥ 10-5 | J11: TBD | K11: =SUMIF(FMEA!$N:$N,J11,FMEA!$S:$S) -> 0 | R11: =R6 -> 4 | S11: =S10 -> 4 | T11: =R11&S11 -> 44 | U11: HI
C12: 2 | D12: Very Little Probable | E12: 10-5 > P ≥ 10-7 | R12: =R7 -> 5 | S12: =S11 -> 4 | T12: =R12&S12 -> 54 | U12: VH
C13: 1 | D13: Extremely Little Probable | E13: P < 10-7 | J13: TOTAL | K13: =SUM(K5:O11) -> 46 | R13: =R8 -> 1 | S13: =J7 -> 3 | T13: =R13&S13 -> 13 | U13: LO
R14: =R9 -> 2 | S14: =S13 -> 3 | T14: =R14&S14 -> 23 | U14: MI
R15: =R10 -> 3 | S15: =S14 -> 3 | T15: =R15&S15 -> 33 | U15: MI
R16: =R11 -> 4 | S16: =S15 -> 3 | T16: =R16&S16 -> 43 | U16: ME
C17: Severity | R17: =R12 -> 5 | S17: =S16 -> 3 | T17: =R17&S17 -> 53 | U17: HI
R18: =R13 -> 1 | S18: =J8 -> 2 | T18: =R18&S18 -> 12 | U18: LO
C19: Class | D19: Severity Designation | E19: Severity Definition | R19: =R14 -> 2 | S19: =S18 -> 2 | T19: =R19&S19 -> 22 | U19: LO
C20: 5 | D20: Catastrophic | E20: 1) Loss of life | R20: =R15 -> 3 | S20: =S19 -> 2 | T20: =R20&S20 -> 32 | U20: MI
E21: 2) Life-threatening or permanently disabling injury or occupational illness | R21: =R16 -> 4 | S21: =S20 -> 2 | T21: =R21&S21 -> 42 | U21: MI
E22: 3) Severe detrimental environmental effects | R22: =R17 -> 5 | S22: =S21 -> 2 | T22: =R22&S22 -> 52 | U22: ME
C23: 4 | D23: Critical | E23: 1) Temporarily disabling but not life-threatening injury, or temporary occupational illness | R23: =R18 -> 1 | S23: =J9 -> 1 | T23: =R23&S23 -> 11 | U23: LO
E24: 2) Major damage to test facilities | R24: =R19 -> 2 | S24: =S23 -> 1 | T24: =R24&S24 -> 21 | U24: LO
E25: 3) Major detrimental environmental effects | R25: =R20 -> 3 | S25: =S24 -> 1 | T25: =R25&S25 -> 31 | U25: LO
C26: 3 | D26: Major | E26: 1) Damage to Test Article with test fail | R26: =R21 -> 4 | S26: =S25 -> 1 | T26: =R26&S26 -> 41 | U26: LO
C27: 1 | D27: Negligible | E27: 1) No or negligible effects | R27: 0 | S27: 0 | T27: =R27&S27 -> 00 | U27: TBD
